DEBUG (29/02/2024 14:28:26): server init (Line: 14 [server.py])
ERROR (29/02/2024 14:28:41): Connect client error || Exception: name 'ip_adress' is not defined (Line: 12 [clients.py])
ERROR (29/02/2024 14:28:41): Connection acception error || Exception:cannot access local variable 'client' where it is not associated with a value (Line: 60 [server.py])
ERROR (29/02/2024 14:28:41): Connection lost with None || Exception:'NoneType' object has no attribute 'recv' (Line: 44 [server.py])
DEBUG (29/02/2024 14:30:18): server init (Line: 14 [server.py])
ERROR (29/02/2024 14:30:23): Connect client error || Exception: 'Client' object has no attribute 'init_access_rights' (Line: 12 [clients.py])
ERROR (29/02/2024 14:30:23): Connection acception error || Exception:cannot access local variable 'client' where it is not associated with a value (Line: 60 [server.py])
ERROR (29/02/2024 14:30:23): Connection lost with None || Exception:'NoneType' object has no attribute 'recv' (Line: 44 [server.py])
DEBUG (29/02/2024 15:07:29): server init (Line: 14 [server.py])
DEBUG (29/02/2024 15:08:57): server init (Line: 14 [server.py])
ERROR (29/02/2024 15:09:03): Connect client error || Exception: Client.__init_access_rights() takes 1 positional argument but 2 were given (Line: 12 [clients.py])
ERROR (29/02/2024 15:09:03): Connection acception error || Exception:cannot access local variable 'client' where it is not associated with a value (Line: 60 [server.py])
ERROR (29/02/2024 15:09:03): Connection lost with None || Exception:'NoneType' object has no attribute 'recv' (Line: 44 [server.py])
DEBUG (29/02/2024 15:09:45): server init (Line: 14 [server.py])
ERROR (29/02/2024 15:09:45): Connect client error || Exception: [Errno 2] No such file or directory: 'clients\\access rights.py' (Line: 12 [clients.py])
ERROR (29/02/2024 15:09:45): Connection acception error || Exception:cannot access local variable 'client' where it is not associated with a value (Line: 60 [server.py])
ERROR (29/02/2024 15:09:45): Connection lost with None || Exception:'NoneType' object has no attribute 'recv' (Line: 44 [server.py])
DEBUG (29/02/2024 15:11:08): server init (Line: 14 [server.py])
ERROR (29/02/2024 15:11:15): Connect client error || Exception: 'str' object has no attribute 'get' (Line: 12 [clients.py])
ERROR (29/02/2024 15:11:15): Connection acception error || Exception:cannot access local variable 'client' where it is not associated with a value (Line: 60 [server.py])
ERROR (29/02/2024 15:11:15): Connection lost with None || Exception:'NoneType' object has no attribute 'recv' (Line: 44 [server.py])
DEBUG (29/02/2024 15:13:17): server init (Line: 14 [server.py])
ERROR (29/02/2024 15:13:26): Connect client error || Exception: name 'priont' is not defined (Line: 12 [clients.py])
ERROR (29/02/2024 15:13:26): Connection acception error || Exception:cannot access local variable 'client' where it is not associated with a value (Line: 60 [server.py])
ERROR (29/02/2024 15:13:26): Connection lost with None || Exception:'NoneType' object has no attribute 'recv' (Line: 44 [server.py])
DEBUG (29/02/2024 15:13:57): server init (Line: 14 [server.py])
ERROR (29/02/2024 15:14:00): Connect client error || Exception: cannot access local variable 'client' where it is not associated with a value (Line: 12 [clients.py])
ERROR (29/02/2024 15:14:00): Connection acception error || Exception:cannot access local variable 'client' where it is not associated with a value (Line: 60 [server.py])
ERROR (29/02/2024 15:14:00): Connection lost with None || Exception:'NoneType' object has no attribute 'recv' (Line: 44 [server.py])
DEBUG (29/02/2024 15:16:20): server init (Line: 14 [server.py])
ERROR (29/02/2024 15:16:29): Connect client error || Exception: cannot access local variable 'client' where it is not associated with a value (Line: 14 [clients.py])
ERROR (29/02/2024 15:16:29): Connection acception error || Exception:cannot access local variable 'client' where it is not associated with a value (Line: 60 [server.py])
ERROR (29/02/2024 15:16:29): Connection lost with None || Exception:'NoneType' object has no attribute 'recv' (Line: 44 [server.py])
DEBUG (29/02/2024 15:19:15): server init (Line: 14 [server.py])
ERROR (29/02/2024 15:19:21): Connect client error || Exception: cannot access local variable 'client' where it is not associated with a value (Line: 13 [clients.py])
ERROR (29/02/2024 15:19:21): Connection acception error || Exception:cannot access local variable 'client' where it is not associated with a value (Line: 60 [server.py])
ERROR (29/02/2024 15:19:21): Connection lost with None || Exception:'NoneType' object has no attribute 'recv' (Line: 44 [server.py])
DEBUG (01/03/2024 12:30:31): server init (Line: 14 [server.py])
ERROR (01/03/2024 12:31:13): Connect client error || Exception: cannot access local variable 'client' where it is not associated with a value (Line: 13 [clients.py])
ERROR (01/03/2024 12:31:13): Connection acception error || Exception:cannot access local variable 'client' where it is not associated with a value (Line: 60 [server.py])
ERROR (01/03/2024 12:31:13): Connection lost with None || Exception:'NoneType' object has no attribute 'recv' (Line: 44 [server.py])
DEBUG (01/03/2024 12:41:01): server init (Line: 14 [server.py])
ERROR (01/03/2024 12:41:08): Connect client error || Exception: 'str' object has no attribute 'get' (Line: 13 [clients.py])
ERROR (01/03/2024 12:41:08): Connection acception error || Exception:cannot access local variable 'client' where it is not associated with a value (Line: 60 [server.py])
ERROR (01/03/2024 12:41:08): Connection lost with None || Exception:'NoneType' object has no attribute 'recv' (Line: 44 [server.py])
DEBUG (01/03/2024 12:46:21): server init (Line: 14 [server.py])
ERROR (01/03/2024 12:46:29): Connect client error || Exception: name 'f' is not defined (Line: 13 [clients.py])
ERROR (01/03/2024 12:46:29): Connection acception error || Exception:cannot access local variable 'client' where it is not associated with a value (Line: 60 [server.py])
ERROR (01/03/2024 12:46:29): Connection lost with None || Exception:'NoneType' object has no attribute 'recv' (Line: 44 [server.py])
DEBUG (01/03/2024 12:48:05): server init (Line: 14 [server.py])
ERROR (01/03/2024 12:48:11): Connect client error || Exception: name 'f' is not defined (Line: 13 [clients.py])
ERROR (01/03/2024 12:48:11): Connection acception error || Exception:cannot access local variable 'client' where it is not associated with a value (Line: 60 [server.py])
ERROR (01/03/2024 12:48:11): Connection lost with None || Exception:'NoneType' object has no attribute 'recv' (Line: 44 [server.py])
DEBUG (01/03/2024 12:50:26): server init (Line: 14 [server.py])
ERROR (01/03/2024 12:50:41): Connect client error || Exception: name 'f' is not defined (Line: 13 [clients.py])
ERROR (01/03/2024 12:50:41): Connection acception error || Exception:cannot access local variable 'client' where it is not associated with a value (Line: 61 [server.py])
ERROR (01/03/2024 12:50:41): Connection lost with None || Exception:'NoneType' object has no attribute 'recv' (Line: 44 [server.py])
DEBUG (01/03/2024 12:58:52): server init (Line: 14 [server.py])
ERROR (01/03/2024 12:58:57): Connect client error || Exception: name 'f' is not defined (Line: 13 [clients.py])
ERROR (01/03/2024 12:58:57): Connection acception error || Exception:cannot access local variable 'client' where it is not associated with a value (Line: 62 [server.py])
ERROR (01/03/2024 12:58:57): Disconnect client error || Exception: cannot unpack non-iterable NoneType object (Line: 26 [clients.py])
DEBUG (01/03/2024 13:00:07): server init (Line: 14 [server.py])
ERROR (01/03/2024 13:00:13): Connect client error || Exception: name 'ip_adress' is not defined (Line: 13 [clients.py])
ERROR (01/03/2024 13:00:13): Connection acception error || Exception:cannot access local variable 'client' where it is not associated with a value (Line: 62 [server.py])
ERROR (01/03/2024 13:00:13): Disconnect client error || Exception: cannot unpack non-iterable NoneType object (Line: 26 [clients.py])
DEBUG (01/03/2024 13:01:29): server init (Line: 14 [server.py])
ERROR (01/03/2024 13:01:34): Connect client error || Exception: 'str' object has no attribute 'get' (Line: 13 [clients.py])
ERROR (01/03/2024 13:01:34): Connection acception error || Exception:cannot access local variable 'client' where it is not associated with a value (Line: 62 [server.py])
ERROR (01/03/2024 13:01:34): Disconnect client error || Exception: cannot unpack non-iterable NoneType object (Line: 26 [clients.py])
DEBUG (01/03/2024 13:05:27): server init (Line: 14 [server.py])
ERROR (01/03/2024 13:05:39): Connect client error || Exception: 'str' object has no attribute 'get' (Line: 13 [clients.py])
ERROR (01/03/2024 13:05:39): Connection acception error || Exception:cannot access local variable 'client' where it is not associated with a value (Line: 62 [server.py])
ERROR (01/03/2024 13:05:39): Disconnect client error || Exception: cannot unpack non-iterable NoneType object (Line: 26 [clients.py])
DEBUG (01/03/2024 13:06:22): server init (Line: 14 [server.py])
ERROR (01/03/2024 13:06:29): Connect client error || Exception: 'str' object has no attribute 'get' (Line: 13 [clients.py])
ERROR (01/03/2024 13:06:29): Connection acception error || Exception:cannot access local variable 'client' where it is not associated with a value (Line: 62 [server.py])
ERROR (01/03/2024 13:06:29): Disconnect client error || Exception: cannot unpack non-iterable NoneType object (Line: 26 [clients.py])
DEBUG (01/03/2024 13:07:24): server init (Line: 14 [server.py])
ERROR (01/03/2024 13:07:31): Connect client error || Exception: 'str' object has no attribute 'get' (Line: 13 [clients.py])
ERROR (01/03/2024 13:07:31): Connection acception error || Exception:cannot access local variable 'client' where it is not associated with a value (Line: 62 [server.py])
ERROR (01/03/2024 13:07:31): Disconnect client error || Exception: cannot unpack non-iterable NoneType object (Line: 26 [clients.py])
DEBUG (01/03/2024 13:10:01): server init (Line: 14 [server.py])
ERROR (01/03/2024 13:10:08): Connect client error || Exception: 'str' object has no attribute 'get' (Line: 13 [clients.py])
ERROR (01/03/2024 13:10:08): Connection acception error || Exception:cannot access local variable 'client' where it is not associated with a value (Line: 62 [server.py])
ERROR (01/03/2024 13:10:08): Disconnect client error || Exception: cannot unpack non-iterable NoneType object (Line: 26 [clients.py])
DEBUG (01/03/2024 13:11:22): server init (Line: 14 [server.py])
ERROR (01/03/2024 13:11:27): Connect client error || Exception: 'str' object has no attribute 'get' (Line: 13 [clients.py])
ERROR (01/03/2024 13:11:27): Connection acception error || Exception:cannot access local variable 'client' where it is not associated with a value (Line: 62 [server.py])
ERROR (01/03/2024 13:11:27): Disconnect client error || Exception: cannot unpack non-iterable NoneType object (Line: 26 [clients.py])
DEBUG (01/03/2024 13:18:47): server init (Line: 14 [server.py])
ERROR (01/03/2024 13:18:53): Connect client error || Exception: string indices must be integers, not 'str' (Line: 13 [clients.py])
ERROR (01/03/2024 13:18:53): Connection acception error || Exception:cannot access local variable 'client' where it is not associated with a value (Line: 62 [server.py])
ERROR (01/03/2024 13:18:53): Disconnect client error || Exception: cannot unpack non-iterable NoneType object (Line: 26 [clients.py])
DEBUG (01/03/2024 13:20:48): server init (Line: 14 [server.py])
ERROR (01/03/2024 13:20:54): Connect client error || Exception: 'Client' object has no attribute '_Client__access_rights' (Line: 13 [clients.py])
ERROR (01/03/2024 13:20:54): Connection acception error || Exception:cannot access local variable 'client' where it is not associated with a value (Line: 62 [server.py])
ERROR (01/03/2024 13:20:54): Disconnect client error || Exception: cannot unpack non-iterable NoneType object (Line: 26 [clients.py])
DEBUG (01/03/2024 13:23:32): server init (Line: 14 [server.py])
ERROR (01/03/2024 13:23:38): Connect client error || Exception: 'Client' object has no attribute '_Client__access_rights' (Line: 13 [clients.py])
ERROR (01/03/2024 13:23:38): Connection acception error || Exception:cannot access local variable 'client' where it is not associated with a value (Line: 62 [server.py])
ERROR (01/03/2024 13:23:38): Disconnect client error || Exception: cannot unpack non-iterable NoneType object (Line: 26 [clients.py])
DEBUG (01/03/2024 13:36:46): server init (Line: 14 [server.py])
ERROR (01/03/2024 13:37:16): Connect client error || Exception: 'Client' object has no attribute '_Client__access_rights' (Line: 13 [clients.py])
ERROR (01/03/2024 13:37:16): Connection acception error || Exception:cannot access local variable 'client' where it is not associated with a value (Line: 62 [server.py])
ERROR (01/03/2024 13:37:16): Disconnect client error || Exception: cannot unpack non-iterable NoneType object (Line: 26 [clients.py])
DEBUG (01/03/2024 13:38:54): server init (Line: 14 [server.py])
ERROR (01/03/2024 13:39:19): Connect client error || Exception: 'Client' object has no attribute '_Client__access_rights' (Line: 13 [clients.py])
ERROR (01/03/2024 13:39:19): Connection acception error || Exception:cannot access local variable 'client' where it is not associated with a value (Line: 62 [server.py])
ERROR (01/03/2024 13:39:19): Disconnect client error || Exception: cannot unpack non-iterable NoneType object (Line: 26 [clients.py])
DEBUG (01/03/2024 15:12:36): server init (Line: 14 [server.py])
ERROR (01/03/2024 15:13:11): Connect client error || Exception: 'Client' object has no attribute '_Client__access_rights' (Line: 13 [clients.py])
ERROR (01/03/2024 15:13:11): Connection acception error || Exception:cannot access local variable 'client' where it is not associated with a value (Line: 62 [server.py])
ERROR (01/03/2024 15:13:11): Disconnect client error || Exception: cannot unpack non-iterable NoneType object (Line: 26 [clients.py])
DEBUG (01/03/2024 15:15:01): server init (Line: 14 [server.py])
ERROR (01/03/2024 15:15:09): Connect client error || Exception: 'Client' object has no attribute '_Client__access_rights' (Line: 13 [clients.py])
ERROR (01/03/2024 15:15:09): Connection acception error || Exception:cannot access local variable 'client' where it is not associated with a value (Line: 62 [server.py])
ERROR (01/03/2024 15:15:09): Disconnect client error || Exception: cannot unpack non-iterable NoneType object (Line: 26 [clients.py])
DEBUG (01/03/2024 15:17:58): server init (Line: 14 [server.py])
DEBUG (01/03/2024 16:07:03): server init (Line: 14 [server.py])
ERROR (01/03/2024 16:07:08): Connect client error || Exception: the JSON object must be str, bytes or bytearray, not TextIOWrapper (Line: 13 [clients.py])
ERROR (01/03/2024 16:07:08): Connection acception error || Exception:cannot access local variable 'client' where it is not associated with a value (Line: 62 [server.py])
ERROR (01/03/2024 16:07:08): Disconnect client error || Exception: cannot unpack non-iterable NoneType object (Line: 26 [clients.py])
DEBUG (01/03/2024 16:08:37): server init (Line: 14 [server.py])
ERROR (01/03/2024 16:08:44): Connect client error || Exception: the JSON object must be str, bytes or bytearray, not TextIOWrapper (Line: 13 [clients.py])
ERROR (01/03/2024 16:08:44): Connection acception error || Exception:cannot access local variable 'client' where it is not associated with a value (Line: 62 [server.py])
ERROR (01/03/2024 16:08:44): Disconnect client error || Exception: cannot unpack non-iterable NoneType object (Line: 26 [clients.py])
DEBUG (01/03/2024 16:23:58): server init (Line: 14 [server.py])
ERROR (01/03/2024 16:24:05): Connect client error || Exception: the JSON object must be str, bytes or bytearray, not TextIOWrapper (Line: 13 [clients.py])
ERROR (01/03/2024 16:24:05): Connection acception error || Exception:cannot access local variable 'client' where it is not associated with a value (Line: 62 [server.py])
ERROR (01/03/2024 16:24:05): Disconnect client error || Exception: cannot unpack non-iterable NoneType object (Line: 26 [clients.py])
DEBUG (01/03/2024 16:25:18): server init (Line: 14 [server.py])
ERROR (01/03/2024 16:25:24): Connect client error || Exception: the JSON object must be str, bytes or bytearray, not TextIOWrapper (Line: 13 [clients.py])
ERROR (01/03/2024 16:25:24): Connection acception error || Exception:cannot access local variable 'client' where it is not associated with a value (Line: 62 [server.py])
ERROR (01/03/2024 16:25:24): Disconnect client error || Exception: cannot unpack non-iterable NoneType object (Line: 26 [clients.py])
DEBUG (01/03/2024 16:26:06): server init (Line: 14 [server.py])
DEBUG (01/03/2024 16:26:12): Connection established from ('127.0.0.1', 64980) (Line: 55 [server.py])
ERROR (01/03/2024 16:26:12): Connection acception error || Exception:deque.append() takes exactly one argument (0 given) (Line: 62 [server.py])
ERROR (01/03/2024 16:26:12): Disconnect client error || Exception: cannot unpack non-iterable NoneType object (Line: 26 [clients.py])
DEBUG (01/03/2024 16:58:56): server init (Line: 14 [server.py])
DEBUG (01/03/2024 17:01:38): server init (Line: 14 [server.py])
ERROR (01/03/2024 17:02:41): Connect client error || Exception: 'dict' object is not callable (Line: 14 [clients.py])
ERROR (01/03/2024 17:02:41): Connection acception error || Exception:cannot access local variable 'client' where it is not associated with a value (Line: 62 [server.py])
ERROR (01/03/2024 17:02:41): Disconnect client error || Exception: cannot unpack non-iterable NoneType object (Line: 27 [clients.py])
DEBUG (04/03/2024 13:00:54): server init (Line: 14 [server.py])
ERROR (04/03/2024 13:01:36): Connection acception error || Exception:connect_client() takes 1 positional argument but 2 were given (Line: 65 [server.py])
DEBUG (04/03/2024 13:04:06): server init (Line: 14 [server.py])
ERROR (04/03/2024 13:04:15): Connection acception error || Exception:connect_client() takes 1 positional argument but 2 were given (Line: 64 [server.py])
DEBUG (04/03/2024 13:12:55): server init (Line: 14 [server.py])
ERROR (04/03/2024 13:13:49): Connect client error || Exception: 'dict' object is not callable (Line: 15 [clients.py])
ERROR (04/03/2024 13:13:49): Connection acception error || Exception:cannot access local variable 'client' where it is not associated with a value (Line: 64 [server.py])
DEBUG (04/03/2024 13:14:48): server init (Line: 14 [server.py])
ERROR (04/03/2024 13:14:54): Connect client error || Exception: 'dict' object is not callable (Line: 18 [clients.py])
ERROR (04/03/2024 13:14:54): Connection acception error || Exception:cannot access local variable 'client' where it is not associated with a value (Line: 64 [server.py])
DEBUG (04/03/2024 13:17:01): server init (Line: 14 [server.py])
ERROR (04/03/2024 13:17:12): Connect client error || Exception: 'dict' object is not callable (Line: 60 [clients.py])
ERROR (04/03/2024 13:17:12): Connection acception error || Exception:cannot access local variable 'client' where it is not associated with a value (Line: 64 [server.py])
DEBUG (04/03/2024 13:20:52): server init (Line: 14 [server.py])
ERROR (04/03/2024 13:21:01): Connect client error || Exception: 'dict' object is not callable (Line: 60 [clients.py])
ERROR (04/03/2024 13:21:01): Connection acception error || Exception:cannot access local variable 'client' where it is not associated with a value (Line: 64 [server.py])
DEBUG (04/03/2024 13:33:29): server init (Line: 14 [server.py])
ERROR (04/03/2024 13:33:35): Connect client error || Exception: name 'address' is not defined (Line: 69 [clients.py])
ERROR (04/03/2024 13:33:35): Connection acception error || Exception:cannot access local variable 'client' where it is not associated with a value (Line: 64 [server.py])
DEBUG (04/03/2024 13:34:12): server init (Line: 14 [server.py])
ERROR (04/03/2024 13:34:21): Connect client error || Exception: name 'address' is not defined (Line: 68 [clients.py])
ERROR (04/03/2024 13:34:21): Connection acception error || Exception:cannot access local variable 'client' where it is not associated with a value (Line: 64 [server.py])
DEBUG (04/03/2024 13:34:43): server init (Line: 14 [server.py])
ERROR (04/03/2024 13:34:50): Connect client error || Exception: 'dict' object is not callable (Line: 68 [clients.py])
ERROR (04/03/2024 13:34:50): Connection acception error || Exception:cannot access local variable 'client' where it is not associated with a value (Line: 64 [server.py])
DEBUG (04/03/2024 13:36:12): server init (Line: 14 [server.py])
ERROR (04/03/2024 13:36:21): Connect client error || Exception: name 'сlient' is not defined (Line: 74 [clients.py])
DEBUG (04/03/2024 13:37:56): server init (Line: 14 [server.py])
DEBUG (04/03/2024 13:38:06): Connection established from ('127.0.0.1', 55416) (Line: 57 [server.py])
ERROR (04/03/2024 13:38:06): Connection acception error || Exception:deque.append() takes exactly one argument (0 given) (Line: 64 [server.py])
DEBUG (04/03/2024 13:39:04): server init (Line: 14 [server.py])
DEBUG (04/03/2024 13:39:08): Connection established from ('127.0.0.1', 55435) (Line: 57 [server.py])
ERROR (04/03/2024 13:39:08): Connection lost with ('127.0.0.1', 55435) || Exception:name 'client_socket' is not defined (Line: 45 [server.py])
DEBUG (04/03/2024 13:39:56): server init (Line: 14 [server.py])
DEBUG (04/03/2024 13:40:11): Connection established from ('127.0.0.1', 55444) (Line: 57 [server.py])
DEBUG (04/03/2024 13:40:27): client: 127.0.0.1 - TIME (Line: 96 [commands.py])
DEBUG (04/03/2024 13:40:32): client: 127.0.0.1 - ECHO (Line: 96 [commands.py])
DEBUG (04/03/2024 13:40:36): client: 127.0.0.1 - TIME (Line: 96 [commands.py])
ERROR (04/03/2024 13:40:38): QUIT Exception: name 'client_socket' is not defined (Line: 41 [commands.py])
DEBUG (04/03/2024 13:40:38): client: 127.0.0.1 - QUIT was not executed (Line: 92 [commands.py])
ERROR (04/03/2024 13:40:39): Connection lost with ('127.0.0.1', 55444) || Exception:[WinError 10054] Удаленный хост принудительно разорвал существующее подключение (Line: 45 [server.py])
DEBUG (04/03/2024 13:40:43): Connection established from ('127.0.0.1', 55446) (Line: 57 [server.py])
DEBUG (04/03/2024 13:40:46): client: 127.0.0.1 - TIME (Line: 96 [commands.py])
DEBUG (04/03/2024 13:40:50): client: 127.0.0.1 - TIME (Line: 96 [commands.py])
ERROR (04/03/2024 13:40:50): Connection lost with ('127.0.0.1', 55446) || Exception:[WinError 10054] Удаленный хост принудительно разорвал существующее подключение (Line: 45 [server.py])
DEBUG (05/03/2024 13:40:19): server init (Line: 14 [server.py])
DEBUG (05/03/2024 13:40:38): Connection established from ('127.0.0.1', 22281) (Line: 57 [server.py])
DEBUG (05/03/2024 13:40:55): client: 127.0.0.1 - TIME (Line: 98 [commands.py])
ERROR (05/03/2024 13:41:21): Command execution error: Client.get_current_catalog() takes 0 positional arguments but 1 was given (Line: 100 [commands.py])
DEBUG (05/03/2024 13:42:17): server init (Line: 14 [server.py])
DEBUG (05/03/2024 13:42:23): Connection established from ('127.0.0.1', 22300) (Line: 57 [server.py])
ERROR (05/03/2024 13:42:24): Command execution error: cannot access local variable 'directories' where it is not associated with a value (Line: 101 [commands.py])
DEBUG (05/03/2024 13:43:06): server init (Line: 14 [server.py])
DEBUG (05/03/2024 13:43:12): Connection established from ('127.0.0.1', 22314) (Line: 57 [server.py])
ERROR (05/03/2024 13:43:38): Command execution error: cannot access local variable 'directories' where it is not associated with a value (Line: 101 [commands.py])
ERROR (05/03/2024 13:43:41): Connection lost with ('127.0.0.1', 22314) || Exception:[WinError 10054] Удаленный хост принудительно разорвал существующее подключение (Line: 45 [server.py])
DEBUG (05/03/2024 13:43:48): server init (Line: 14 [server.py])
DEBUG (05/03/2024 13:43:54): Connection established from ('127.0.0.1', 22321) (Line: 57 [server.py])
ERROR (05/03/2024 13:43:56): Command execution error: cannot access local variable 'directories' where it is not associated with a value (Line: 101 [commands.py])
DEBUG (07/03/2024 13:30:16): server init (Line: 14 [server.py])
DEBUG (07/03/2024 13:31:00): Connection established from ('127.0.0.1', 63621) (Line: 57 [server.py])
ERROR (07/03/2024 13:31:13): Command execution error: cannot access local variable 'directories' where it is not associated with a value (Line: 101 [commands.py])
DEBUG (07/03/2024 13:36:46): server init (Line: 14 [server.py])
DEBUG (07/03/2024 13:36:53): Connection established from ('127.0.0.1', 62022) (Line: 57 [server.py])
ERROR (07/03/2024 13:36:56): Command execution error: cannot access local variable 'directories' where it is not associated with a value (Line: 101 [commands.py])
DEBUG (07/03/2024 13:37:47): server init (Line: 14 [server.py])
DEBUG (07/03/2024 13:37:53): Connection established from ('127.0.0.1', 62032) (Line: 57 [server.py])
ERROR (07/03/2024 13:37:55): Command execution error: list index out of range (Line: 101 [commands.py])
DEBUG (07/03/2024 13:39:20): server init (Line: 14 [server.py])
DEBUG (07/03/2024 13:39:26): Connection established from ('127.0.0.1', 62065) (Line: 57 [server.py])
ERROR (07/03/2024 13:39:27): Command execution error: list index out of range (Line: 101 [commands.py])
DEBUG (07/03/2024 13:40:00): server init (Line: 14 [server.py])
DEBUG (07/03/2024 13:40:05): Connection established from ('127.0.0.1', 62085) (Line: 57 [server.py])
DEBUG (07/03/2024 13:40:06): client: 127.0.0.1 - LS was not executed (Line: 95 [commands.py])
DEBUG (07/03/2024 13:41:13): server init (Line: 14 [server.py])
DEBUG (07/03/2024 13:41:21): server init (Line: 14 [server.py])
DEBUG (07/03/2024 13:41:25): Connection established from ('127.0.0.1', 62096) (Line: 57 [server.py])
ERROR (07/03/2024 13:41:26): Connection lost with ('127.0.0.1', 62096) || Exception:[WinError 10054] Удаленный хост принудительно разорвал существующее подключение (Line: 45 [server.py])
DEBUG (07/03/2024 13:41:32): server init (Line: 14 [server.py])
DEBUG (07/03/2024 13:41:42): Connection established from ('127.0.0.1', 62099) (Line: 57 [server.py])
DEBUG (07/03/2024 13:41:44): client: 127.0.0.1 - LS was not executed (Line: 96 [commands.py])
DEBUG (07/03/2024 13:44:02): server init (Line: 14 [server.py])
DEBUG (07/03/2024 13:45:30): server init (Line: 14 [server.py])
DEBUG (07/03/2024 13:45:34): Connection established from ('127.0.0.1', 62166) (Line: 57 [server.py])
DEBUG (07/03/2024 13:47:06): client: 127.0.0.1 - LS was not executed (Line: 96 [commands.py])
ERROR (07/03/2024 13:47:21): Connection lost with ('127.0.0.1', 62166) || Exception:[WinError 10054] Удаленный хост принудительно разорвал существующее подключение (Line: 45 [server.py])
DEBUG (07/03/2024 13:48:58): server init (Line: 14 [server.py])
DEBUG (07/03/2024 13:49:02): Connection established from ('127.0.0.1', 62206) (Line: 57 [server.py])
DEBUG (07/03/2024 13:49:05): client: 127.0.0.1 - LIST was not executed (Line: 96 [commands.py])
ERROR (07/03/2024 13:49:07): Connection lost with ('127.0.0.1', 62206) || Exception:[WinError 10054] Удаленный хост принудительно разорвал существующее подключение (Line: 45 [server.py])
DEBUG (07/03/2024 14:21:33): server init (Line: 14 [server.py])
DEBUG (07/03/2024 14:22:01): Connection established from ('127.0.0.1', 44676) (Line: 57 [server.py])
DEBUG (07/03/2024 14:22:05): client: 127.0.0.1 - TIME (Line: 100 [commands.py])
DEBUG (07/03/2024 14:22:07): client: 127.0.0.1 - LS was not executed (Line: 96 [commands.py])
DEBUG (07/03/2024 14:27:47): server init (Line: 14 [server.py])
DEBUG (07/03/2024 14:27:49): Connection established from ('127.0.0.1', 44677) (Line: 57 [server.py])
DEBUG (07/03/2024 14:27:53): client: 127.0.0.1 - LS was not executed (Line: 96 [commands.py])
DEBUG (07/03/2024 14:29:10): server init (Line: 14 [server.py])
DEBUG (07/03/2024 14:29:14): Connection established from ('127.0.0.1', 44678) (Line: 57 [server.py])
DEBUG (07/03/2024 14:29:19): client: 127.0.0.1 - LS was not executed (Line: 96 [commands.py])
DEBUG (07/03/2024 14:30:36): server init (Line: 14 [server.py])
DEBUG (07/03/2024 14:30:38): Connection established from ('127.0.0.1', 44679) (Line: 57 [server.py])
DEBUG (07/03/2024 14:31:23): server init (Line: 14 [server.py])
DEBUG (07/03/2024 14:31:26): Connection established from ('127.0.0.1', 44680) (Line: 57 [server.py])
ERROR (07/03/2024 14:31:39): Connection lost with ('127.0.0.1', 44680) || Exception:[WinError 10054] Удаленный хост принудительно разорвал существующее подключение (Line: 45 [server.py])
DEBUG (07/03/2024 14:31:51): server init (Line: 14 [server.py])
DEBUG (07/03/2024 14:31:53): Connection established from ('127.0.0.1', 44681) (Line: 57 [server.py])
DEBUG (07/03/2024 14:31:58): client: 127.0.0.1 - LS was not executed (Line: 96 [commands.py])
DEBUG (07/03/2024 14:34:07): server init (Line: 14 [server.py])
DEBUG (07/03/2024 14:34:08): Connection established from ('127.0.0.1', 10387) (Line: 57 [server.py])
DEBUG (07/03/2024 14:34:11): client: 127.0.0.1 - LS was not executed (Line: 96 [commands.py])
DEBUG (07/03/2024 14:34:14): client: 127.0.0.1 - TIME (Line: 100 [commands.py])
DEBUG (12/03/2024 00:38:10): server init (Line: 14 [server.py])
DEBUG (12/03/2024 00:43:12): server init (Line: 14 [server.py])
DEBUG (12/03/2024 00:43:17): Connection established from ('127.0.0.1', 37449) (Line: 57 [server.py])
DEBUG (12/03/2024 00:44:03): client: 127.0.0.1 - TIME (Line: 100 [commands.py])
DEBUG (12/03/2024 00:44:15): client: 127.0.0.1 - ECHO (Line: 100 [commands.py])
DEBUG (12/03/2024 00:44:16): client: 127.0.0.1 - ECHO (Line: 100 [commands.py])
ERROR (12/03/2024 00:44:18): QUIT Exception: name 'client_socket' is not defined (Line: 42 [commands.py])
DEBUG (12/03/2024 00:44:18): client: 127.0.0.1 - QUIT was not executed (Line: 96 [commands.py])
ERROR (12/03/2024 00:44:20): Command execution error: list index out of range (Line: 102 [commands.py])
ERROR (12/03/2024 00:44:23): Connection lost with ('127.0.0.1', 37449) || Exception:[WinError 10054] Удаленный хост принудительно разорвал существующее подключение (Line: 45 [server.py])
DEBUG (12/03/2024 00:45:31): server init (Line: 14 [server.py])
DEBUG (12/03/2024 00:45:33): Connection established from ('127.0.0.1', 37457) (Line: 57 [server.py])
DEBUG (12/03/2024 00:45:39): client: 127.0.0.1 - LIST was not executed (Line: 96 [commands.py])
DEBUG (12/03/2024 00:46:01): client: 127.0.0.1 - LIST was not executed (Line: 96 [commands.py])
DEBUG (12/03/2024 00:48:16): server init (Line: 14 [server.py])
DEBUG (12/03/2024 00:48:22): Connection established from ('127.0.0.1', 37482) (Line: 57 [server.py])
DEBUG (12/03/2024 00:48:30): client: 127.0.0.1 - LIST was not executed (Line: 96 [commands.py])
DEBUG (12/03/2024 00:50:04): server init (Line: 14 [server.py])
DEBUG (12/03/2024 00:50:07): Connection established from ('127.0.0.1', 37487) (Line: 57 [server.py])
DEBUG (12/03/2024 00:50:11): client: 127.0.0.1 - LIST was not executed (Line: 96 [commands.py])
DEBUG (12/03/2024 00:51:38): server init (Line: 14 [server.py])
DEBUG (12/03/2024 00:51:40): Connection established from ('127.0.0.1', 37513) (Line: 57 [server.py])
DEBUG (12/03/2024 00:52:26): server init (Line: 14 [server.py])
DEBUG (12/03/2024 00:52:31): Connection established from ('127.0.0.1', 37521) (Line: 57 [server.py])
DEBUG (12/03/2024 00:53:40): server init (Line: 14 [server.py])
DEBUG (12/03/2024 00:53:42): Connection established from ('127.0.0.1', 37526) (Line: 57 [server.py])
DEBUG (12/03/2024 00:54:23): server init (Line: 14 [server.py])
DEBUG (12/03/2024 00:54:29): Connection established from ('127.0.0.1', 37530) (Line: 57 [server.py])
DEBUG (12/03/2024 00:56:36): server init (Line: 14 [server.py])
ERROR (12/03/2024 00:56:39): Connect client error || Exception: 'Client' object has no attribute 'address' (Line: 71 [clients.py])
ERROR (12/03/2024 00:56:39): Connection acception error || Exception:cannot access local variable 'client' where it is not associated with a value (Line: 64 [server.py])
ERROR (12/03/2024 00:57:02): Connect client error || Exception: 'Client' object has no attribute 'address' (Line: 71 [clients.py])
ERROR (12/03/2024 00:57:02): Connection acception error || Exception:cannot access local variable 'client' where it is not associated with a value (Line: 64 [server.py])
DEBUG (12/03/2024 00:59:43): server init (Line: 14 [server.py])
DEBUG (12/03/2024 00:59:45): Connection established from ('127.0.0.1', 37555) (Line: 57 [server.py])
DEBUG (12/03/2024 00:59:48): client: 127.0.0.1 - LIST was not executed (Line: 96 [commands.py])
ERROR (12/03/2024 01:00:16): QUIT Exception: name 'client_socket' is not defined (Line: 42 [commands.py])
DEBUG (12/03/2024 01:00:16): client: 127.0.0.1 - QUIT was not executed (Line: 96 [commands.py])
ERROR (12/03/2024 01:00:20): Connection lost with ('127.0.0.1', 37555) || Exception:[WinError 10054] Удаленный хост принудительно разорвал существующее подключение (Line: 45 [server.py])
DEBUG (12/03/2024 01:04:52): server init (Line: 14 [server.py])
DEBUG (12/03/2024 01:04:55): Connection established from ('127.0.0.1', 37575) (Line: 57 [server.py])
DEBUG (12/03/2024 01:04:58): client: 127.0.0.1 - LIST was not executed (Line: 100 [commands.py])
DEBUG (12/03/2024 01:05:04): client: 127.0.0.1 - TIME (Line: 104 [commands.py])
ERROR (12/03/2024 01:05:05): Connection lost with ('127.0.0.1', 37575) || Exception:[WinError 10054] Удаленный хост принудительно разорвал существующее подключение (Line: 45 [server.py])
DEBUG (12/03/2024 01:14:07): server init (Line: 14 [server.py])
DEBUG (12/03/2024 01:14:10): Connection established from ('127.0.0.1', 37617) (Line: 61 [server.py])
DEBUG (12/03/2024 01:14:18): client: 127.0.0.1 - LIST (Line: 107 [commands.py])
ERROR (12/03/2024 01:14:20): Command execution error: list index out of range (Line: 109 [commands.py])
ERROR (12/03/2024 01:14:23): Command execution error: list index out of range (Line: 109 [commands.py])
DEBUG (12/03/2024 01:14:25): client: 127.0.0.1 - TIME (Line: 107 [commands.py])
ERROR (12/03/2024 01:14:45): QUIT Exception: name 'client_socket' is not defined (Line: 42 [commands.py])
DEBUG (12/03/2024 01:14:45): client: 127.0.0.1 - QUIT was not executed (Line: 103 [commands.py])
ERROR (12/03/2024 01:14:49): Connection lost with ('127.0.0.1', 37617) || Exception:[WinError 10054] Удаленный хост принудительно разорвал существующее подключение (Line: 49 [server.py])
DEBUG (12/03/2024 01:17:46): server init (Line: 14 [server.py])
DEBUG (12/03/2024 01:17:54): Connection established from ('127.0.0.1', 37634) (Line: 57 [server.py])
ERROR (12/03/2024 01:17:56): Command execution error: list index out of range (Line: 112 [commands.py])
ERROR (12/03/2024 01:17:59): Command execution error: list index out of range (Line: 112 [commands.py])
ERROR (12/03/2024 01:17:59): Command execution error: list index out of range (Line: 112 [commands.py])
ERROR (12/03/2024 01:17:59): Command execution error: list index out of range (Line: 112 [commands.py])
ERROR (12/03/2024 01:18:00): Command execution error: list index out of range (Line: 112 [commands.py])
ERROR (12/03/2024 01:18:00): Command execution error: list index out of range (Line: 112 [commands.py])
ERROR (12/03/2024 01:18:00): Command execution error: list index out of range (Line: 112 [commands.py])
ERROR (12/03/2024 01:18:00): Command execution error: list index out of range (Line: 112 [commands.py])
ERROR (12/03/2024 01:18:01): Command execution error: list index out of range (Line: 112 [commands.py])
ERROR (12/03/2024 01:18:01): Command execution error: list index out of range (Line: 112 [commands.py])
ERROR (12/03/2024 01:18:01): Command execution error: list index out of range (Line: 112 [commands.py])
ERROR (12/03/2024 01:18:01): Command execution error: list index out of range (Line: 112 [commands.py])
DEBUG (12/03/2024 01:18:04): client: 127.0.0.1 - TIME (Line: 107 [commands.py])
ERROR (12/03/2024 01:18:10): Command execution error: list index out of range (Line: 112 [commands.py])
ERROR (12/03/2024 01:18:10): Command execution error: list index out of range (Line: 112 [commands.py])
ERROR (12/03/2024 01:18:11): Connection lost with ('127.0.0.1', 37634) || Exception:[WinError 10054] Удаленный хост принудительно разорвал существующее подключение (Line: 45 [server.py])
DEBUG (12/03/2024 01:20:37): server init (Line: 14 [server.py])
DEBUG (12/03/2024 01:20:50): Connection established from ('127.0.0.1', 37651) (Line: 58 [server.py])
ERROR (12/03/2024 01:20:52): Command execution error: list index out of range (Line: 116 [commands.py])
ERROR (12/03/2024 01:20:52): Connection lost with ('127.0.0.1', 37651) || Exception:name 'send_current_dir' is not defined (Line: 46 [server.py])
DEBUG (12/03/2024 01:22:15): server init (Line: 14 [server.py])
DEBUG (12/03/2024 01:22:31): Connection established from ('127.0.0.1', 37659) (Line: 58 [server.py])
ERROR (12/03/2024 01:22:31): Connection acception error || Exception:'Client' object has no attribute 'split' (Line: 66 [server.py])
DEBUG (12/03/2024 01:24:03): server init (Line: 14 [server.py])
DEBUG (12/03/2024 01:24:06): Connection established from ('127.0.0.1', 37667) (Line: 58 [server.py])
ERROR (12/03/2024 01:24:06): Connection acception error || Exception:list index out of range (Line: 66 [server.py])
DEBUG (12/03/2024 01:27:32): server init (Line: 14 [server.py])
DEBUG (12/03/2024 01:27:35): Connection established from ('127.0.0.1', 37678) (Line: 57 [server.py])
ERROR (12/03/2024 01:27:35): Command execution error: list index out of range (Line: 116 [commands.py])
DEBUG (12/03/2024 01:28:27): server init (Line: 14 [server.py])
DEBUG (12/03/2024 01:28:31): Connection established from ('127.0.0.1', 37683) (Line: 57 [server.py])
ERROR (12/03/2024 01:28:31): Command execution error: list index out of range (Line: 116 [commands.py])
DEBUG (12/03/2024 01:30:25): server init (Line: 14 [server.py])
DEBUG (12/03/2024 01:30:28): Connection established from ('127.0.0.1', 37687) (Line: 57 [server.py])
DEBUG (12/03/2024 01:30:28): client: 127.0.0.1 - TIME (Line: 113 [commands.py])
DEBUG (12/03/2024 01:30:36): client: 127.0.0.1 - TIME (Line: 113 [commands.py])
DEBUG (12/03/2024 01:30:44): client: 127.0.0.1 - ECHO (Line: 113 [commands.py])
DEBUG (12/03/2024 01:30:48): client: 127.0.0.1 - LIST (Line: 113 [commands.py])
ERROR (12/03/2024 01:30:50): Command execution error: list index out of range (Line: 116 [commands.py])
ERROR (12/03/2024 01:30:52): Command execution error: list index out of range (Line: 116 [commands.py])
ERROR (12/03/2024 01:30:52): Command execution error: list index out of range (Line: 116 [commands.py])
ERROR (12/03/2024 01:30:52): Command execution error: list index out of range (Line: 116 [commands.py])
ERROR (12/03/2024 01:30:53): Command execution error: list index out of range (Line: 116 [commands.py])
ERROR (12/03/2024 01:30:53): Command execution error: list index out of range (Line: 116 [commands.py])
ERROR (12/03/2024 01:31:03): Connection lost with ('127.0.0.1', 37687) || Exception:[WinError 10054] Удаленный хост принудительно разорвал существующее подключение (Line: 45 [server.py])
DEBUG (12/03/2024 01:34:44): server init (Line: 14 [server.py])
DEBUG (12/03/2024 01:34:46): Connection established from ('127.0.0.1', 37701) (Line: 57 [server.py])
DEBUG (12/03/2024 01:34:46): client: 127.0.0.1 - TIME (Line: 114 [commands.py])
ERROR (12/03/2024 01:34:48): Command execution error: list index out of range (Line: 117 [commands.py])
ERROR (12/03/2024 01:34:50): Command execution error: list index out of range (Line: 117 [commands.py])
ERROR (12/03/2024 01:34:51): Command execution error: list index out of range (Line: 117 [commands.py])
ERROR (12/03/2024 01:34:51): Command execution error: list index out of range (Line: 117 [commands.py])
ERROR (12/03/2024 01:34:51): Command execution error: list index out of range (Line: 117 [commands.py])
DEBUG (12/03/2024 01:34:54): client: 127.0.0.1 - TIME (Line: 114 [commands.py])
ERROR (12/03/2024 01:35:03): Connection lost with ('127.0.0.1', 37701) || Exception:[WinError 10054] Удаленный хост принудительно разорвал существующее подключение (Line: 45 [server.py])
DEBUG (12/03/2024 01:37:52): server init (Line: 14 [server.py])
DEBUG (12/03/2024 01:37:55): Connection established from ('127.0.0.1', 37728) (Line: 58 [server.py])
ERROR (12/03/2024 01:37:55): Connection acception error || Exception:list index out of range (Line: 66 [server.py])
DEBUG (12/03/2024 01:39:13): server init (Line: 14 [server.py])
DEBUG (12/03/2024 01:39:16): Connection established from ('127.0.0.1', 37736) (Line: 58 [server.py])
ERROR (12/03/2024 01:39:18): Command execution error: list index out of range (Line: 117 [commands.py])
ERROR (12/03/2024 01:39:18): Connection lost with ('127.0.0.1', 37736) || Exception:list index out of range (Line: 46 [server.py])
DEBUG (12/03/2024 01:42:23): server init (Line: 14 [server.py])
DEBUG (12/03/2024 01:42:28): Connection established from ('127.0.0.1', 37750) (Line: 60 [server.py])
ERROR (12/03/2024 01:42:29): Command execution error: list index out of range (Line: 117 [commands.py])
ERROR (12/03/2024 01:42:29): Connection lost with ('127.0.0.1', 37750) || Exception:list index out of range (Line: 48 [server.py])
DEBUG (12/03/2024 01:44:27): server init (Line: 14 [server.py])
DEBUG (12/03/2024 01:44:53): Connection established from ('127.0.0.1', 37759) (Line: 60 [server.py])
DEBUG (12/03/2024 01:45:03): client: 127.0.0.1 - TIME (Line: 115 [commands.py])
DEBUG (12/03/2024 01:45:08): client: 127.0.0.1 - ECHO (Line: 115 [commands.py])
ERROR (12/03/2024 01:45:12): QUIT Exception: name 'client_socket' is not defined (Line: 42 [commands.py])
DEBUG (12/03/2024 01:45:12): client: 127.0.0.1 - QUIT was not executed (Line: 111 [commands.py])
ERROR (12/03/2024 01:45:17): Connection lost with ('127.0.0.1', 37759) || Exception:[WinError 10054] Удаленный хост принудительно разорвал существующее подключение (Line: 48 [server.py])
DEBUG (12/03/2024 01:45:24): Connection established from ('127.0.0.1', 37766) (Line: 60 [server.py])
DEBUG (12/03/2024 01:45:26): client: 127.0.0.1 - TIME (Line: 115 [commands.py])
ERROR (12/03/2024 01:45:27): Connection lost with ('127.0.0.1', 37766) || Exception:[WinError 10054] Удаленный хост принудительно разорвал существующее подключение (Line: 48 [server.py])
DEBUG (12/03/2024 01:49:43): server init (Line: 14 [server.py])
DEBUG (12/03/2024 01:49:48): Connection established from ('127.0.0.1', 37780) (Line: 60 [server.py])
DEBUG (12/03/2024 01:49:50): client: 127.0.0.1 - TIME (Line: 114 [commands.py])
DEBUG (12/03/2024 01:50:33): client: 127.0.0.1 - LS (Line: 114 [commands.py])
DEBUG (12/03/2024 01:50:36): client: 127.0.0.1 - LIST (Line: 114 [commands.py])
ERROR (12/03/2024 01:50:40): QUIT Exception: name 'client_socket' is not defined (Line: 42 [commands.py])
DEBUG (12/03/2024 01:50:40): client: 127.0.0.1 - QUIT was not executed (Line: 110 [commands.py])
ERROR (12/03/2024 01:50:45): Connection lost with ('127.0.0.1', 37780) || Exception:[WinError 10054] Удаленный хост принудительно разорвал существующее подключение (Line: 48 [server.py])
DEBUG (12/03/2024 01:51:05): server init (Line: 14 [server.py])
DEBUG (12/03/2024 01:51:12): Connection established from ('127.0.0.1', 37785) (Line: 60 [server.py])
DEBUG (12/03/2024 01:51:13): client: 127.0.0.1 - LS (Line: 114 [commands.py])
DEBUG (12/03/2024 01:51:26): client: 127.0.0.1 - CD was not executed (Line: 110 [commands.py])
DEBUG (12/03/2024 01:51:34): client: 127.0.0.1 - CD was not executed (Line: 110 [commands.py])
DEBUG (12/03/2024 01:52:28): server init (Line: 14 [server.py])
DEBUG (12/03/2024 01:52:33): Connection established from ('127.0.0.1', 37790) (Line: 60 [server.py])
DEBUG (12/03/2024 01:52:34): client: 127.0.0.1 - LS (Line: 115 [commands.py])
DEBUG (12/03/2024 01:52:36): client: 127.0.0.1 - CD was not executed (Line: 111 [commands.py])
DEBUG (12/03/2024 01:53:35): server init (Line: 14 [server.py])
DEBUG (12/03/2024 01:53:40): Connection established from ('127.0.0.1', 37796) (Line: 60 [server.py])
DEBUG (12/03/2024 01:53:40): client: 127.0.0.1 - LS (Line: 116 [commands.py])
DEBUG (12/03/2024 01:53:43): client: 127.0.0.1 - CD was not executed (Line: 112 [commands.py])
DEBUG (12/03/2024 01:55:43): server init (Line: 14 [server.py])
DEBUG (12/03/2024 01:55:49): Connection established from ('127.0.0.1', 37803) (Line: 60 [server.py])
DEBUG (12/03/2024 01:55:51): client: 127.0.0.1 - CD (Line: 116 [commands.py])
DEBUG (12/03/2024 01:59:27): server init (Line: 14 [server.py])
DEBUG (12/03/2024 01:59:34): Connection established from ('127.0.0.1', 37821) (Line: 60 [server.py])
DEBUG (12/03/2024 01:59:38): client: 127.0.0.1 - LIST - list
 (Line: 117 [commands.py])
DEBUG (12/03/2024 01:59:41): client: 127.0.0.1 - CD - cd root\private
 (Line: 117 [commands.py])
ERROR (12/03/2024 01:59:41): Connection lost with ('127.0.0.1', 37821) || Exception:can only concatenate list (not "str") to list (Line: 48 [server.py])
DEBUG (12/03/2024 02:01:36): server init (Line: 14 [server.py])
DEBUG (12/03/2024 02:01:42): Connection established from ('127.0.0.1', 37831) (Line: 60 [server.py])
DEBUG (12/03/2024 02:01:44): client: 127.0.0.1 - TIME (Line: 118 [commands.py])
DEBUG (12/03/2024 02:01:48): client: 127.0.0.1 - LS (Line: 118 [commands.py])
DEBUG (12/03/2024 02:01:50): client: 127.0.0.1 - CD (Line: 118 [commands.py])
DEBUG (12/03/2024 02:02:57): server init (Line: 14 [server.py])
DEBUG (12/03/2024 02:03:04): Connection established from ('127.0.0.1', 37835) (Line: 60 [server.py])
DEBUG (12/03/2024 02:03:08): client: 127.0.0.1 - CD (Line: 117 [commands.py])
DEBUG (12/03/2024 02:03:12): client: 127.0.0.1 - LIST (Line: 117 [commands.py])
DEBUG (12/03/2024 02:03:20): client: 127.0.0.1 - CD (Line: 117 [commands.py])
ERROR (12/03/2024 02:03:21): Connection lost with ('127.0.0.1', 37835) || Exception:[WinError 10054] Удаленный хост принудительно разорвал существующее подключение (Line: 48 [server.py])
DEBUG (12/03/2024 02:14:55): server init (Line: 11 [server.py])
DEBUG (12/03/2024 02:22:38): server init (Line: 12 [server.py])
DEBUG (12/03/2024 02:22:43): Connection established from ('127.0.0.1', 37987) (Line: 59 [server.py])
DEBUG (12/03/2024 02:22:47): client: 127.0.0.1 - LIST (Line: 121 [commands.py])
ERROR (12/03/2024 02:22:53): CD Exception: argument of type 'NoneType' is not iterable (Line: 63 [commands.py])
DEBUG (12/03/2024 02:22:53): client: 127.0.0.1 - CD was not executed (Line: 117 [commands.py])
DEBUG (12/03/2024 02:24:13): server init (Line: 12 [server.py])
DEBUG (12/03/2024 02:24:17): Connection established from ('127.0.0.1', 37992) (Line: 59 [server.py])
ERROR (12/03/2024 02:24:29): Connection lost with ('127.0.0.1', 37992) || Exception:[WinError 10054] Удаленный хост принудительно разорвал существующее подключение (Line: 47 [server.py])
DEBUG (12/03/2024 02:27:03): server init (Line: 12 [server.py])
DEBUG (12/03/2024 02:27:09): Connection established from ('127.0.0.1', 38005) (Line: 59 [server.py])
ERROR (12/03/2024 02:27:11): CD Exception: argument of type 'NoneType' is not iterable (Line: 66 [commands.py])
DEBUG (12/03/2024 02:27:11): client: 127.0.0.1 - CD was not executed (Line: 120 [commands.py])
DEBUG (12/03/2024 02:32:36): server init (Line: 12 [server.py])
DEBUG (12/03/2024 02:32:47): Connection established from ('127.0.0.1', 38032) (Line: 59 [server.py])
DEBUG (12/03/2024 02:32:48): client: 127.0.0.1 - CD was not executed (Line: 120 [commands.py])
DEBUG (12/03/2024 02:33:23): server init (Line: 12 [server.py])
DEBUG (12/03/2024 02:33:28): Connection established from ('127.0.0.1', 38041) (Line: 59 [server.py])
DEBUG (12/03/2024 02:33:30): client: 127.0.0.1 - CD was not executed (Line: 121 [commands.py])
DEBUG (12/03/2024 02:53:28): server init (Line: 12 [server.py])
DEBUG (12/03/2024 02:53:33): Connection established from ('127.0.0.1', 38176) (Line: 59 [server.py])
DEBUG (12/03/2024 02:53:34): client: 127.0.0.1 - CD was not executed (Line: 121 [commands.py])
ERROR (12/03/2024 02:54:00): Connection lost with ('127.0.0.1', 38176) || Exception:[WinError 10054] Удаленный хост принудительно разорвал существующее подключение (Line: 47 [server.py])
DEBUG (12/03/2024 02:54:48): server init (Line: 12 [server.py])
DEBUG (12/03/2024 02:54:56): Connection established from ('127.0.0.1', 38184) (Line: 59 [server.py])
DEBUG (12/03/2024 02:54:58): client: 127.0.0.1 - CD was not executed (Line: 121 [commands.py])
DEBUG (12/03/2024 21:09:20): server init (Line: 11 [server.py])
DEBUG (13/03/2024 14:16:58): server init (Line: 15 [server.py])
DEBUG (13/03/2024 14:17:02): server init (Line: 15 [server.py])
DEBUG (13/03/2024 14:17:08): Connection established from ('127.0.0.1', 6286) (Line: 62 [server.py])
DEBUG (13/03/2024 14:17:11): client: 127.0.0.1 - LIST (Line: 125 [commands.py])
DEBUG (13/03/2024 14:17:16): client: 127.0.0.1 - TIME (Line: 125 [commands.py])
DEBUG (13/03/2024 14:17:22): client: 127.0.0.1 - ECHO (Line: 125 [commands.py])
ERROR (13/03/2024 14:17:25): QUIT Exception: name 'client_socket' is not defined (Line: 42 [commands.py])
DEBUG (13/03/2024 14:17:25): client: 127.0.0.1 - QUIT was not executed (Line: 121 [commands.py])
ERROR (13/03/2024 14:17:26): Connection lost with ('127.0.0.1', 6286) || Exception:[WinError 10054] Удаленный хост принудительно разорвал существующее подключение (Line: 50 [server.py])
DEBUG (13/03/2024 14:32:06): Connection established from ('127.0.0.1', 6629) (Line: 62 [server.py])
DEBUG (13/03/2024 14:32:13): client: 127.0.0.1 - ECHO (Line: 125 [commands.py])
DEBUG (13/03/2024 14:32:16): client: 127.0.0.1 - TIME (Line: 125 [commands.py])
DEBUG (13/03/2024 14:32:20): client: 127.0.0.1 - LS (Line: 125 [commands.py])
ERROR (13/03/2024 14:32:23): QUIT Exception: name 'client_socket' is not defined (Line: 42 [commands.py])
DEBUG (13/03/2024 14:32:23): client: 127.0.0.1 - QUIT was not executed (Line: 121 [commands.py])
ERROR (13/03/2024 14:32:24): Connection lost with ('127.0.0.1', 6629) || Exception:[WinError 10054] Удаленный хост принудительно разорвал существующее подключение (Line: 50 [server.py])
DEBUG (13/03/2024 14:36:30): server init (Line: 15 [server.py])
DEBUG (13/03/2024 14:39:46): Connection established from ('127.0.0.1', 6747) (Line: 62 [server.py])
DEBUG (13/03/2024 14:40:01): client: 127.0.0.1 - LIST (Line: 125 [commands.py])
DEBUG (18/03/2024 12:59:44): server init (Line: 15 [server.py])
DEBUG (18/03/2024 13:00:42): Connection established from ('127.0.0.1', 36642) (Line: 62 [server.py])
ERROR (18/03/2024 13:00:42): Connection lost with ('127.0.0.1', 36642) || Exception:[WinError 10054] Удаленный хост принудительно разорвал существующее подключение (Line: 50 [server.py])
DEBUG (18/03/2024 13:24:37): server init (Line: 15 [server.py])
DEBUG (18/03/2024 13:26:06): Connection established from ('127.0.0.1', 36888) (Line: 62 [server.py])
DEBUG (18/03/2024 13:26:06): Connection lost with ('127.0.0.1', 36888) (Line: 39 [server.py])
DEBUG (18/03/2024 13:27:33): Connection established from ('127.0.0.1', 36920) (Line: 62 [server.py])
DEBUG (18/03/2024 13:27:36): client: 127.0.0.1 - LIST (Line: 125 [commands.py])
DEBUG (18/03/2024 13:28:09): client: 127.0.0.1 - LS (Line: 125 [commands.py])
